# SPDX-License-Identifier: AGPL-3.0-or-later
#
# SPDX-FileCopyrightText: 2023 JWP Consulting GK
"""Test task model and manager."""

from django import db

import pytest

from ... import models


@pytest.mark.django_db
class TestTask:
    """Test Task."""

    def test_factory(self, section: models.Section, task: models.Task) -> None:
        """Test that section is assigned correctly."""
        assert task.section == section
        assert task.due_date is not None

    def test_get_next_section(
        self,
        project: models.Project,
        task: models.Task,
        other_section: models.Section,
    ) -> None:
        """Test getting the next section."""
        assert task.get_next_section() == other_section

    def test_get_next_section_no_next_section(
        self, project: models.Project, task: models.Task
    ) -> None:
        """Test getting the next section when there is none."""
        with pytest.raises(models.Section.DoesNotExist):
            task.get_next_section()

    def test_task_number(
        self, task: models.Task, other_task: models.Task
    ) -> None:
        """Test unique task number."""
        other_task.refresh_from_db()
        task.refresh_from_db()
        assert other_task.number == task.number + 1
        task.workspace.refresh_from_db()
        assert task.workspace.highest_task_number == other_task.number

    def test_save(self, task: models.Task) -> None:
        """Test saving and assert number does not change."""
        num = task.number
        task.save()
        assert task.number == num

    def test_save_no_number(
        self, task: models.Task, workspace: models.Workspace
    ) -> None:
        """Test saving with no number."""
        # With psycopg2 we had an db.InternalError, now with psycopg 3 it
        # became db.ProgrammingError instead
        with pytest.raises(db.ProgrammingError):
            task.number = None  # type: ignore[assignment]
            task.save()
            workspace.refresh_from_db()

    def test_save_different_number(self, task: models.Task) -> None:
        """Test saving with different number."""
        # Changed from db.InternalError, see above in test_save_no_number
        with pytest.raises(db.ProgrammingError):
            task.number = 154785787
            task.save()

    def test_task_workspace_pgtrigger(
        self, task: models.Task, unrelated_workspace: models.Workspace
    ) -> None:
        """Test database trigger for wrong workspace assignment."""
        # Changed from db.InternalError, see above in test_save_no_number
        with pytest.raises(db.ProgrammingError):
            task.workspace = unrelated_workspace
            task.save()
